Workbook

Sheet Tools
C2: Tool Name | D2: References | E2: Year | F2: Authors/Institution | G2: Discovery Method | H2: Discovered From | I2: Selection Status | J2: Exclusion Reason | K2: Short Description
C3: PowerScope | D3: Noureddine, Adel, Romain Rouvoy, and Lionel Seinturier. 2013. ‘A Review of Energy Measurement Approaches’. SIGOPS Oper. Syst. Rev. 47 (3): 42–49. https://doi.org/10.1145/2553070.2553077. PowerScope: A Tool for Profiling the Energy Usage of Mobileapplications’. n.d. ResearchGate. https://doi.org/10.1109/MCSA.1999.749272. | E3: 1999 | F3: Jason Flinn and M. Satyanarayanan | G3: Backward Snawballing | I3: Not Selected | K3: PowerScope is historically interesting because its architecture explicitly separates data collection from energy-profile generation. A dedicated second computer controls the external multimeter and collects the power samples, while the profiling computer only performs lightweight system-activity sampling. The collected data are then processed offline, so the energy-analysis stage introduces no profiling overhead. It also provides an interesting early form of hardware-specific attribution: in (Flinn and Satyanarayanan 1999) samples occurring during asynchronous interrupts are not attributed to the currently executing process, but to a dedicated interrupt bucket. For example, WaveLAN interrupts are separately accounted for, allowing network-related energy to be distinguished from the process that happened to be executing. This is particularly noteworthy in our study because, so far, PowerScope is the only tool we have identified that explicitly allocates energy associated with hardware interrupts to a specific hardware component/activity. Nevertheless, we exclude it from the classification because of its age, its reliance on NetBSD kernel modifications and a uniprocessor architecture, and the lack of a currently available tool implementation.
C4: RAPL | D4: Khan, Kashif Nizam, Mikael Hirki, Tapio Niemi, Jukka K. Nurminen, and Zhonghong Ou. 2018. ‘RAPL in Action: Experiences in Using RAPL for Power Measurements’. ACM Trans. Model. Perform. Eval. Comput. Syst. 3 (2): 9:1-9:26. https://doi.org/10.1145/3177754. Chekushkin, Artem, Vitaly Egunov, Alla G. Kravets, and Pavel Kravchenya. 2026. ‘Software Methods for Energy Consumption Evaluation’. In Frontiers of Industrial Cyber-Physics, edited by Alla G. Kravets, Alexander A. Bolshakov, and Maxim V. Shcherbakov. Springer Nature Switzerland. https://doi.org/10.1007/978-3-032-02717-7_8. | E4: 2010 | F4: Intel | G4: Seeds (Extensively used in scientific litterature and a primitive for other tools such as GMT Kepler,… | H4: na | I4: Not Selected | J4: No software-level attribution | K4: RAPL (Running Average Power Limit) is a hardware-level energy monitoring and power-controlling interface introduced by Intel for its processors. It exposes energy consumption estimates via Model-Specific Registers (MSRs), allowing software to read energy usage for specific hardware domains.
C5: e-Surgeon (= Jalen + PowerAPI) | D5: Noureddine, Adel, Romain Rouvoy, and Lionel Seinturier. 2015. ‘Monitoring Energy Hotspots in Software’. Automated Software Engineering 22 (3): 291–332. https://doi.org/10.1007/s10515-014-0171-1. Noureddine, Adel, Aurélien Bourdon, Romain Rouvoy, and Lionel Seinturier. 2012. E-Surgeon: Diagnosing Energy Leaks of Application Servers. Technical Report RR-7846. INRIA. https://inria.hal.science/hal-00652992. | E5: 2012 | F5: Noureddine, Adel, Romain Rouvoy, and Lionel Seinturier. | G5: Seeds (Keywords Search) | H5: Manual keyword search on Google Scholar : "Software energy monitoring" | I5: Selected | J5: na | K5: e-Surgeon is a software-based energy profiling framework that estimates fine-grained (method-level) power consumption of Java applications at runtime. It combines operating-system-level hardware monitoring (PowerAPI) with either bytecode instrumentation or statistical sampling (Jalen), using analytical and empirical power models to estimate application energy consumption without relying on external power meters.
C6: PowerGadget | D6: Wysocki, Włodzimierz, Ireneusz Miciuła, and Przemysław Plecka. 2025. ‘Methods of Improving Software Energy Efficiency: A Systematic Literature Review and the Current State of Applied Methods in Practice’. Electronics 14 (7): 1331. https://doi.org/10.3390/electronics14071331. | E6: 2014 | F6: Intel | G6: Backward Snawballing | H6: (Wysocki et al. 2025) | I6: Not Selected | J6: No software-level attribution | K6: Intel(r) Power Gadget is a software utility and library, which allows developers to monitor power at very fine time granularities (few tens of milliseconds). Power monitoring is available for the following power domains: per package domain (CPU socket) per core domain (all the cpu cores on a package) per uncore domain (uncore components, e.g. integrated graphics, client parts only) per memory node (memory local to a package, server parts only) To do this, the tool uses an architected capability in Intel(r) processors which is called RAPL (Runtime Average Power Limiting). RAPL is available on Intel(r) codename Sandy Bridge and later processors.
C7: jRAPL | D7: Liu, Kenan, Gustavo Pinto, and Yu David Liu. 2015. ‘Data-Oriented Characterization of Application-Level Energy Optimization’. In Fundamental Approaches to Software Engineering, edited by Alexander Egyed and Ina Schaefer. Springer. https://doi.org/10.1007/978-3-662-46675-9_21. | E7: 2015 | F7: Kenan Liu | G7: Backward Snawballing | H7: (Wysocki et al. 2025) | I7: Selected | J7: na | K7: jRAPL is a Java library that allows to profile the energy consumption of parts of program code by relying on RAPL. To use it, the developer just needs to put API calls (statCheck) before and after a code block. The energy consumption is then computed as the difference between the two readings. It can also report time metrics (wall-clock, user, kernel time) and some low-level counters, which can be useful for analysis. It allows a fine-grained attribution, both in terms of hardware components (RAPL usual granularity) and program structure (methods, code blocks…). Also, since the measurement is directly embedded in the code, there is no need to synchronise measurement and execution, which is usually a pain with external setups. It is not completely free: accessing MSRs introduces a small overhead (microseconds), even if in practice it remains quite low compared to execution time. Overall, jRAPL can be seen as a hardware-based energy metering approach, with relatively low overhead and good granularity, but at the cost of some code instrumentation. (Liu et al. 2015)
C8: IgProf | D8: Khan, Kashif, Filip Nybäck, Zhonghong Ou, et al. 2015. Energy Profiling Using IgProf. In Proceedings - 2015 IEEE/ACM 15th International Symposium on Cluster, Cloud, and Grid Computing, CCGrid 2015. https://doi.org/10.1109/CCGrid.2015.118. G. Eulisse, L. Tuura: IgProf profiling tool, Proc. Computing In High Energy And Nuclear Physics (CHEP 2004), Interlaken, Switzerland, 2004 | E8: 2015 | F8: Lassi Tuura, Giulio, Mikko Kurkela and Filip Nybäck | G8: Backward Snawballing | H8: (Wysocki et al. 2025) | I8: Selected | J8: na | K8: IgProf is originally an application profiler developed at CERN to analyse performance and memory behaviour of programs, and was later extended with an energy profiling module. This module enables the attribution of energy consumption within a program, typically at the level of functions. The approach relies on statistical sampling. IgProf is injected into the target application as a shared library at startup, allowing it to operate entirely within the same process address space. It performs statistical sampling using interval timers and signal handlers, which execute in the context of the application thread. At each sampling point, the profiler captures the current call stack and associates it with energy measurements obtained via RAPL (through PAPI), enabling in-process attribution of energy consumption to functions.. This allows building energy profiles in the same way as traditional performance profiles (e.g., flat profiles (cumulated energy offunction and called sub-function) or call graphs) One advantage is that IgProf operates entirely in user space and does not require recompilation of the application. This makes it relatively non-intrusive compared to instrumentation-based approaches. It can also handle dynamically loaded libraries, which is useful in complex software stacks. In terms of granularity, the tool provides fine-grained attribution at function level, but this is based on sampling and indirect attribution rather than exact measurement. As a result, short-lived code sections (shorter than the RAPL update interval, ~1 ms) may not be measured accurately, and multi-threaded scenarios introduce additional challenges in attributing energy correctly. (Khan et al. 2015) Overall, IgProf can be seen as a sampling-based, hardware-informed energy profiling approach. It offers good integration with performance profiling and low intrusiveness, but with limitations in accuracy for short events and complex concurrent workloads.
C9: BitWatts | D9: Wysocki, Włodzimierz, Ireneusz Miciuła, and Przemysław Plecka. 2025. ‘Methods of Improving Software Energy Efficiency: A Systematic Literature Review and the Current State of Applied Methods in Practice’. Electronics 14 (7): 1331. https://doi.org/10.3390/electronics14071331. Colmant, Maxime, Mascha Kurpicz, Pascal Felber, Loïc Huertas, Romain Rouvoy, and Anita Sobe. 2015. ‘Process-Level Power Estimation in VM-Based Systems’. Proceedings of the Tenth European Conference on Computer Systems (New York, NY, USA), EuroSys ’15, 1–14. https://doi.org/10.1145/2741948.2741971. Colmant, Maxime, Mascha Kurpicz, Pascal Felber, Loïc Huertas, Romain Rouvoy, and Anita Sobe. 2014. ‘BitWatts: A Process-Level Power Monitoring Middleware’. Proceedings of the Posters and Demos Session of the 15th International Middleware Conference (New York, NY, USA), Middleware Posters and Demos ’14, 41–42. https://doi.org/10.1145/2678508.2678529. | E9: 2015 | F9: Maxime Colmant, Mascha Kurpicz, Pascal Felber, Loïc Huertas, Romain Rouvoy, Anita Sobe | G9: Backward Snawballing | H9: (Wysocki et al. 2025) | I9: Selected | J9: na | K9: BITWATTS, an extension of PowerAPI, is a software-defined power meter that supports virtualised environments through two instances: one on the host, which estimates VM power, and one in the guest, which receives this value via a VirtioSerial channel and attributes it to guest processes. Its power source is a processor-aware multivariate regression model based on HPCs, notably unhalted CPU cycles, and CPU frequency. It provides process-level attribution and accounts for multi-core execution, Hyper-Threading, SpeedStep/DVFS, and Turbo Boost. The tool can report at up to 40 Hz with PowerSpy or 10 Hz with libpfm4, although experiments generally use 1 Hz. It was evaluated on Intel Core i3-2120 and Xeon W3520 systems using KVM/QEMU.
C10: GreenOracle | D10: Wysocki, Włodzimierz, Ireneusz Miciuła, and Przemysław Plecka. 2025. ‘Methods of Improving Software Energy Efficiency: A Systematic Literature Review and the Current State of Applied Methods in Practice’. Electronics 14 (7): 1331. https://doi.org/10.3390/electronics14071331. Chowdhury, Shaiful Alam, and Abram Hindle. 2016. ‘GreenOracle: Estimating Software Energy Consumption with Energy Measurement Corpora’. Proceedings of the 13th International Conference on Mining Software Repositories (New York, NY, USA), MSR ’16, 49–60. https://doi.org/10.1145/2901739.2901763. | E10: 2016 | F10: Shaiful Alam Chowdhury, Abram Hindle | G10: Backward Snawballing | H10: (Wysocki et al. 2025) | I10: Not Selected | J10: Mobile-only platforms and no software-level attribution | K10: GreenOracle is primarily a mobile application energy prediction model, so it falls outside our survey scope. It estimates the total energy of an Android application test run from system-call counts, CPU utilisation, and other /proc-based resource metrics. The energy model is trained on measurements from many other applications using ridge regression, making it a pretrained, cross-application model that does not require direct energy measurement of the application under test.
C11: Jolinar | D11: Wysocki, Włodzimierz, Ireneusz Miciuła, and Przemysław Plecka. 2025. ‘Methods of Improving Software Energy Efficiency: A Systematic Literature Review and the Current State of Applied Methods in Practice’. Electronics 14 (7): 1331. https://doi.org/10.3390/electronics14071331. Noureddine, Adel, Syed Islam, and Rabih Bashroush. 2016. ‘Jolinar: Analysing the Energy Footprint of Software Applications (Demo)’. Proceedings of the 25th International Symposium on Software Testing and Analysis, July 18, 445–48. https://doi.org/10.1145/2931037.2948706. | E11: 2016 | F11: Adel Noureddine, Syed Islam, Rabih Bashroush | G11: Backward Snawballing | H11: (Wysocki et al. 2025) | I11: Not Selected | J11: Deprecated | K11: Jolinar is a lightweight GNU/Linux application-level energy monitoring tool built on top of PowerAPI. It estimates application energy from OS-provided resource utilisation and hardware specifications, using models for CPU, disk and memory; the CPU model accounts for DVFS and real-time frequency/voltage changes. It monitors one application at a time, limited to one process per application, with a temporal resolution of 500 ms.
C12: Stress-Terminal UI | D12: Centofanti, Carlo, José Santos, Venkateswarlu Gudepu, and Koteswararao Kondepu. 2024. ‘Impact of Power Consumption in Containerized Clouds: A Comprehensive Analysis of Open-Source Power Measurement Tools’. Computer Networks 245 (May): 110371. https://doi.org/10.1016/j.comnet.2024.110371. | E12: 2017 | F12: Alex Manos | G12: Backward Snawballing | H12: (Centofanti et al. 2024) | I12: Not Selected | J12: No software-level attribution | K12: Stress Terminal UI (s-tui) is an open-source monitoring tool that provides real-time visualisation of system performance and power-related metrics. It reads data from hardware interfaces such as Intel RAPL and system sensors to display CPU usage, frequency, temperature, and estimated power consumption. Designed as a terminal-based interface, it is mainly used for local monitoring and stress testing on Linux systems rather than fine-grained software energy attribution.
C13: Scaphandre | D13: Centofanti, Carlo, José Santos, Venkateswarlu Gudepu, and Koteswararao Kondepu. 2024. ‘Impact of Power Consumption in Containerized Clouds: A Comprehensive Analysis of Open-Source Power Measurement Tools’. Computer Networks 245 (May): 110371. https://doi.org/10.1016/j.comnet.2024.110371. | E13: 2020 | F13: Hubblo-org | G13: Backward Snawballing | H13: (Centofanti et al. 2024) | I13: Selected | J13: na | K13: Scaphandre is an open-source energy monitoring agent developed by Hubblo. It uses Intel RAPL to measure CPU (and optionally DRAM) energy at the system level and attributes it to processes or containers based on CPU usage. It runs as a lightweight daemon and exports metrics to Prometheus, enabling integration in cloud and container environments. Accuracy is high at system level but limited for fine-grained attribution.
C14: Android Runner | D14: Wysocki, Włodzimierz, Ireneusz Miciuła, and Przemysław Plecka. 2025. ‘Methods of Improving Software Energy Efficiency: A Systematic Literature Review and the Current State of Applied Methods in Practice’. Electronics 14 (7): 1331. https://doi.org/10.3390/electronics14071331. Malavolta, Ivano, Eoin Martino Grua, Cheng-Yu Lam, et al. 2021. ‘A Framework for the Automatic Execution of Measurement-Based Experiments on Android Devices’. Proceedings of the 35th IEEE/ACM International Conference on Automated Software Engineering (New York, NY, USA), ASE ’20, January 22, 61–66. https://doi.org/10.1145/3417113.3422184. | E14: 2020 | F14: Ivano Malavolta, Eoin Martino Grua, Cheng-Yu Lam, Randy de Vries, Franky Tan, EricZielinski, Michael Peters, Luuk Kaandorp | G14: Backward Snawballing | H14: (Wysocki et al. 2025) | I14: Not Selected | J14: Mobile-only platforms | K14: Android Runner (AR), a framework for automatically executing measurement-based experiments on native and web apps running on Android devices. In AR, an experiment is defined once in a descriptive fashion, and then its execution is fully automatic, customizable, and replicable. AR is implemented in Python and it can be extended with third-party profilers.
C15: PowerJoular/JoularJX | D15: Noureddine, Adel. (2021) 2022. ‘PowerJoular and JoularJX: Multi-Platform Software Power Monitoring Tools’. In Proceedings of the 18th International Conference on Intelligent Environments, Ada. Intelligent Environments. March 22; IEEE, released. https://doi.org/10.1109/IE54923.2022.9826760. | E15: 2021 | F15: Noureddine, Adel | G15: Backward Snawballing | H15: (Wysocki et al. 2025) | I15: Selected | J15: na | K15: PowerJoular monitors the power consumption of CPU and GPU for PCs, servers and single-board computers (such as Raspberry Pi). JoularJX uses the power data provided by PowerJoular to monitor the power consumption of methods and source code in Java applications. These tools extend the strategies used for former PowerAPI/eJalen : runtime estimation are now possible
... C18: Andro Watts | D18: Guégain, Édouard, Rémy Raes, Noé Chachignot, Clément Quinton, and Romain Rouvoy. 2025. ‘AndroWatts: Unpacking the Power Consumption of Mobile Device’s Components’. 2025 IEEE/ACM 12th International Conference on Mobile Software Engineering and Systems (MOBILESoft), April, 71–81. https://doi.org/10.1109/MOBILESoft66462.2025.00015. | E18: 2025 | F18: Guégain, Édouard, Rémy Raes, Noé Chachignot, Clément Quinton, and Romain Rouvoy. | G18: Seeds (Keywords Search) | H18: na | I18: Not Selected | J18: No software-level attribution Smartphone only platforms | K18: Target device is a smartphone. The authors use supervised learning to train models (linear, nn, random forest, …) to estimate (i) system-level energy (ii) component-level shares of enregy i.e. CPU, display, WIFi, Memory,… Both based on component-related metrics (e.g. display brightness, CPU frequency,...) . The framework involves the creation of a dataset: create scenarios putting the device under a random workload. Then collect features i.e. component-related metrics, and ODPM power rails values as target variables. The study shows Gradient boosting trees estimate best (i). Linear regression is used to estimate (ii): CPU/Memory, GPU, Display energy consumption are successfully estimated while CPU/Memory block has highest accuracy (absolute error ~7%) Under that case study, the authors show they need at least 500 runs (capping the dataset size) to have a stable R-squared
C19: Joular Core | E19: 2026 | F19: Noureddine, Adel | G19: Forward Snawballing | H19: (Noureddine [2021] 2022) | I19: Selected | J19: na | K19: Extension of PowerJoular to MacOs and Windows in a cross-platform implementation written in Rust. Joular Core is designed to be embedded in larger workflows. It exposes power data through multiple channels — terminal, CSV files, a shared-memory ring buffer, and an HTTP/WebSocket API — so it can feed into whatever downstream system you are working with. Also add a GUI for live monitoring
C20: PETRA | G20: Backward Snawballing | H20: (Wysocki et al. 2025) | I20: Not Selected | J20: Mobile-only platforms | K20: PETrA is a software-based energy profiling tool specifically designed for Android applications. It estimates energy at method level, combining Android system information on component states (CPU, Wi-Fi, GPS, etc.) and voltage with a device power profile; method energy is reconstructed from the time intervals during which the method executes.
C21: Green Kube
C22: Trepn | D22: Wysocki, Włodzimierz, Ireneusz Miciuła, and Przemysław Plecka. 2025. ‘Methods of Improving Software Energy Efficiency: A Systematic Literature Review and the Current State of Applied Methods in Practice’. Electronics 14 (7): 1331. https://doi.org/10.3390/electronics14071331. Ahmad, Raja Wasim, Siti Hafizah Ab Hamid, Abdullah Gani, et al. 2018. ‘Performance Assessment of Dynamic Analysis Based Energy Estimation Tools’. 2018 International Symposium on Performance Evaluation of Computer and Telecommunication Systems (SPECTS), July, 1–12. https://doi.org/10.1109/SPECTS.2018.8574182. | G22: Backward Snawballing | H22: (Wysocki et al. 2025) | I22: Not Selected | J22: Mobile-only platforms insufficient documentation | K22: Trepn Profiler is a device power modeling and performance measurement tool to estimate the energy of the device, components, and smartphone applications.
C41: SoftWatt | D41: from Li, Tao, and Lizy Kurian John. 2003. ‘Run-Time Modeling and Estimation of Operating System Power Consumption’. Proceedings of the 2003 ACM SIGMETRICS International Conference on Measurement and Modeling of Computer Systems (New York, NY, USA), SIGMETRICS ’03, 160–71. https://doi.org/10.1145/781027.781048.
C42: pTop | D42: from Noureddine, Adel, Romain Rouvoy, and Lionel Seinturier. 2013. ‘A Review of Energy Measurement Approaches’. SIGOPS Oper. Syst. Rev. 47 (3): 42–49. https://doi.org/10.1145/2553070.2553077.
C43: PowerTop | D43: from Noureddine, Adel, Romain Rouvoy, and Lionel Seinturier. 2013. ‘A Review of Energy Measurement Approaches’. SIGOPS Oper. Syst. Rev. 47 (3): 42–49. https://doi.org/10.1145/2553070.2553077.
C44: Energy Checker | D44: from Noureddine, Adel, Romain Rouvoy, and Lionel Seinturier. 2013. ‘A Review of Energy Measurement Approaches’. SIGOPS Oper. Syst. Rev. 47 (3): 42–49. https://doi.org/10.1145/2553070.2553077.
C45: Joulemeter | D45: from Noureddine, Adel, Romain Rouvoy, and Lionel Seinturier. 2013. ‘A Review of Energy Measurement Approaches’. SIGOPS Oper. Syst. Rev. 47 (3): 42–49. https://doi.org/10.1145/2553070.2553077.
C46: websitecarbon.com
C47: https://aknostic.com/keit/
C48: SmartWatts | D48: from Raffin, Guillaume, and Denis Trystram. 2024. ‘Dissecting the Software-Based Measurement of CPU Energy Consumption: A Comparative Analysis’. arXiv:2401.15985. Preprint, arXiv, July 19. https://doi.org/10.48550/arXiv.2401.15985. Guillaume Fieni, Romain Rouvoy, and Lionel Seinturier. “SmartWatts: self-calibrating software-defined power meter for containers”. en. In: 2020 20th IEEE/ACM International Symposium on Cluster, Cloud and Internet Computing (CCGRID). Melbourne, Australia: IEEE, May 2020, pp. 479–488. ISBN: 978-172816-095-5. DOI: 10 . 1109 / CCGrid49817 . 2020 . 00 45.
C49: ??? | D49: from Raffin, Guillaume, and Denis Trystram. 2024. ‘Dissecting the Software-Based Measurement of CPU Energy Consumption: A Comparative Analysis’. arXiv:2401.15985. Preprint, arXiv, July 19. https://doi.org/10.48550/arXiv.2401.15985. Franz Christian Heinrich et al. “Predicting the energyconsumption of MPI applications at scale using only a single node”. In: 2017 IEEE International Conference on Cluster Computing (CLUSTER). Sept. 2017, pp. 92102. DOI: 10.1109/CLUSTER.2017.66.
C50: Code-Carbon | D50: from Raffin, Guillaume, and Denis Trystram. 2024. ‘Dissecting the Software-Based Measurement of CPU Energy Consumption: A Comparative Analysis’. arXiv:2401.15985. Preprint, arXiv, July 19. https://doi.org/10.48550/arXiv.2401.15985. Victor Schmidt et al. “CodeCarbon: estimate and track carbon emissions from machine learning computing”. In: Zenodo (2021).
C51: Likwid | D51: from Raffin, Guillaume, and Denis Trystram. 2024. ‘Dissecting the Software-Based Measurement of CPU Energy Consumption: A Comparative Analysis’. arXiv:2401.15985. Preprint, arXiv, July 19. https://doi.org/10.48550/arXiv.2401.15985. J. Treibig, G. Hager, and G. Wellein. “LIKWID: a lightweight performance-oriented tool suite for x86 multicore environments”. In: Proceedings of PSTI2010, the First International Workshop on Parallel Software Tools and Tool Infrastructures. San Diego CA, 2010.

Sheet Inclusion Exclusion
B2: Tool Name | C2: Scientific grounding (yes or no) | D2: Software energy profiling (yes or no) | E2: Representative execution environments (yes or no) | F2: Insufficient documentation | G2: Purely theoretical models | H2: Mobile-only platforms | I2: Inclusion Status
B3: Green Metric Tool | C3: yes | D3: yes | E3: yes | F3: no | G3: no | H3: no | I3: =IF(AND(C3="yes",D3="yes",E3="yes",F3="no",G3="no",H3="no"),"Selected","Not Selected") -> Selected
B4: Kepler | C4: yes | D4: yes | E4: yes | F4: no | G4: no | H4: no | I4: =IF(AND(C4="yes",D4="yes",E4="yes",F4="no",G4="no",H4="no"),"Selected","Not Selected") -> Selected
B5: e-Surgeon | C5: yes | D5: yes | E5: yes | F5: no | G5: no | H5: no | I5: =IF(AND(C5="yes",D5="yes",E5="yes",F5="no",G5="no",H5="no"),"Selected","Not Selected") -> Selected
B6: RAPL | C6: yes | D6: no | E6: yes | F6: no | G6: no | H6: no | I6: =IF(AND(C6="yes",D6="yes",E6="yes",F6="no",G6="no",H6="no"),"Selected","Not Selected") -> Not Selected
B7: Scaphandre | C7: yes | D7: yes | E7: yes | F7: no | G7: no | H7: no | I7: =IF(AND(C7="yes",D7="yes",E7="yes",F7="no",G7="no",H7="no"),"Selected","Not Selected") -> Selected
B8: Andro Watts | C8: yes | D8: no | E8: yes | F8: no | G8: no | H8: yes | I8: =IF(AND(C8="yes",D8="yes",E8="yes",F8="no",G8="no",H8="no"),"Selected","Not Selected") -> Not Selected
B9: Stress-Terminal UI | C9: no | D9: no | E9: yes | F9: no | G9: no | H9: no | I9: =IF(AND(C9="yes",D9="yes",E9="yes",F9="no",G9="no",H9="no"),"Selected","Not Selected") -> Not Selected
B10: `PowerJoular/JoularJX | C10: yes | D10: yes | E10: yes | F10: no | G10: no | H10: no | I10: =IF(AND(C10="yes",D10="yes",E10="yes",F10="no",G10="no",H10="no"),"Selected","Not Selected") -> Selected
B11: Power Watts | C11: yes | D11: yes | E11: yes | F11: no | G11: no | I11: =IF(AND(C11="yes",D11="yes",E11="yes",F11="no",G11="no",H11="no"),"Selected","Not Selected") -> Not Selected
B12: jRAPL | C12: yes | D12: yes | E12: yes | F12: no | G12: no | H12: no | I12: =IF(AND(C12="yes",D12="yes",E12="yes",F12="no",G12="no",H12="no"),"Selected","Not Selected") -> Selected
B13: BitWatts | C13: yes | D13: yes | E13: yes | F13: no | G13: no | H13: no | I13: =IF(AND(C13="yes",D13="yes",E13="yes",F13="no",G13="no",H13="no"),"Selected","Not Selected") -> Selected
B14: Trepn | C14: yes | D14: yes | E14: yes | F14: yes | G14: no | H14: yes | I14: =IF(AND(C14="yes",D14="yes",E14="yes",F14="no",G14="no",H14="no"),"Selected","Not Selected") -> Not Selected
B15: PowerGadget | C15: yes | D15: no | E15: yes | F15: no | G15: no | H15: no | I15: =IF(AND(C15="yes",D15="yes",E15="yes",F15="no",G15="no",H15="no"),"Selected","Not Selected") -> Not Selected
B16: Android Runner | C16: yes | D16: yes | E16: yes | F16: no | G16: no | H16: yes | I16: =IF(AND(C16="yes",D16="yes",E16="yes",F16="no",G16="no",H16="no"),"Selected","Not Selected") -> Not Selected
B17: GreenOracle | C17: yes | D17: no | E17: yes | F17: no | G17: no | H17: yes | I17: =IF(AND(C17="yes",D17="yes",E17="yes",F17="no",G17="no",H17="no"),"Selected","Not Selected") -> Not Selected
B18: PowerScope | C18: yes | D18: yes | E18: no | F18: yes | G18: yes | H18: no | I18: =IF(AND(C18="yes",D18="yes",E18="yes",F18="no",G18="no",H18="no"),"Selected","Not Selected") -> Not Selected
I19: =IF(AND(C19="yes",D19="yes",E19="yes",F19="no",G19="no",H19="no"),"Selected","Not Selected") -> Not Selected
I20: =IF(AND(C20="yes",D20="yes",E20="yes",F20="no",G20="no",H20="no"),"Selected","Not Selected") -> Not Selected
I21: =IF(AND(C21="yes",D21="yes",E21="yes",F21="no",G21="no",H21="no"),"Selected","Not Selected") -> Not Selected

Sheet Classification
B2: Tool Name | C2: Measurement level and attribution | P2: Methodology and accuracy | W2: Invasiveness and usability | Z2: Execution environment support | AM2: Maturity and ecosystem
C3: Measurement Targets | J3: Metrics | N3: Granularity | O3: Temporal resolution | P3: Measurement approach | T3: Baseline Modeled and Calibration requirements | U3: Accuracy validation | V3: Repeatability | W3: Code modification | X3: Runtime overhead | Y3: Deployment complexity | Z3: Target Devices | AD3: Supported ISA | AH3: Virtual machines | AI3: Containers | AJ3: Kubernetes integration | AK3: Multi-tenancy awareness | AL3: Cloud provider compatibility | AM3: Availability and licensing | AN3: Maintenance status | AO3: Documentation quality | AP3: Case Studies | AQ3: Community adoption
C4: CPU | D4: DRAM | E4: GPU | F4: Network (NIC) | G4: Storage (Disk) | H4: Display | I4: System | J4: Power/ Energy | K4: Network I/O | L4: Disk I/O | M4: CO2e | P4: External Power Meter | Q4: Hardware-Exposed Energy Interface | R4: Model -based | S4: Attribution Mechanism | Z4: Desktop/ Laptop | AA4: Server | AB4: Mobile Device | AC4: Embedded System | AD4: x86 | AE4: ARM | AF4: RISC-V | AG4: MacSilicon
B5: Green Metric Tool | C5: ✗(RAPL) | D5: ✗(RAPL) | E5: ✗ | F5: no | G5: no | H5: no | I5: ✗ | J5: ✗ | K5: ✗ | L5: ✗ | M5: ✗ | N5: Container-level attribution Application-level (if containerised) | O5: ~ms Configurable for each metric provider (1ms for RAPL metric provider) | P5: ✗(If provided as system input) | Q5: ✗ (RAPL) | R5: trained model for system-level estimations in virtualised contex | S5: Container Isolation : Accesses cgroups to learn about how resources are shared. | T5: Baseline modeled and allocated to container according to CPU % utilisation | U5: Relative to metric providers : For RAPL which is extensively used by the GMT : https://www.green-coding.io/case-studies/rapl-and-sgx/ | V5: Allows periodic checks of the standard deviations of measurments through their "measurement cluster". | W5: No | X5: Designed to be low (uses containers). GMT allows to estimate it through a special script : calibrate.py | Y5: Python App + Redis DB + Web-based API & Front-end for data analysis Hosted Service (paid) | Z5: ✗ (Linux System) | AA5: ✗ | AB5: no | AC5: no | AD5: ✗ (Linux Targeted) | AE5: Few Metric Providers with limited Accuracy | AF5: no | AG5: Depends on Metric Provider in Use | AH5: Limited support but some model-based metric providers allow to account for virtualisation level (e.g. PSU Energy - AC - XGBoost - Machine) | AI5: ✗ | AJ5: no (Doc says "in development" https://docs.green-coding.io/) | AK5: no | AL5: no | AM5: Open-Source | AN5: Active (Last Commit in Feb 2026) | AO5: Extensive Documentation (https://docs.green-coding.io/) | AP5: Hoffmann, Geerd-Dietger, and Verena Majuntke. 2025. ‘Green Metrics Tool: Measuring for Fun and Profit’. arXiv:2506.23967. Preprint, arXiv, June 30. https://doi.org/10.48550/arXiv.2506.23967. Kayembe, Jason, Iness Ben Guirat, and Jan Tobias Mühlberg. 2025. ‘Exploring Privacy and Security as Drivers for Environmental Sustainability in Cloud-Based Office Solutions’. arXiv:2506.23866. Preprint, arXiv, July 4. https://doi.org/10.48550/arXiv.2506.23866. | AQ5: Designed for developers to integrate SCI in dev Used in a few academic researches
B6: Kepler | C6: ✗(RAPL) | D6: ✗(RAPL) | E6: ✗(NVLM) | F6: no | G6: no | H6: no | I6: ✗(IPMI, ACPI, Regression-based trained power models) | J6: ✗ | K6: no | L6: no | M6: no | N6: Node Level (BM/VM) Pod-Level Container-Level Process-level | O6: ~ms at RAPL read level Effective resolution = Prometheus scrape interval (typically 1s–30s depending on configuration) | P6: no | Q6: ✗ (RAPL, NVLM, IPMI) | R6: no | S6: Attribution based on Hardware Counters in (Bare-Metal deployment version) e.g., CPU instruction, cache misses, Streaming Multiprocessor utilisation System-level Energy estimated through Regression-based trained power models for VM deployment | T6: Modeled and allocated according to processes size | U6: Reported MSE of 0.01 in (Amaral et al. 2023) | W6: no | Y6: Runs as DaemonSet on each node Linux-based nodes required | Z6: ✗ (Linux System) | AA6: ✗ | AB6: no | AC6: no | AD6: ✗ (Linux Targeted) | AE6: no | AF6: no | AG6: no | AH6: System-level Energy estimated through Regression-based trained power models for VM deployment | AI6: ✗ | AJ6: ✗ | AK6: Aware of resource sharing at node-level At hypervisor-level : not currently but (CNCF 2023) mentions a planned "passthrough" mode for VM deployment which could enable this | AL6: no (AWS EKS, GKE, Azure AKS do not expose RAPL) | AM6: Open-Source (CNCF Sandbox project) | AN6: Active (Last Commit in March 2026) | AO6: Extensive Documentation (https://sustainable-computing.io/) | AP6: Centofanti, Carlo, José Santos, Venkateswarlu Gudepu, and Koteswararao Kondepu. 2024. ‘Impact of Power Consumption in Containerized Clouds: A Comprehensive Analysis of Open-Source Power Measurement Tools’. Computer Networks 245 (May): 110371. https://doi.org/10.1016/j.comnet.2024.110371. | AQ6: Designed for edge/cloud/ K8s Operators
B7: e-Surgeon (PowerAPI+eJalen) | C7: ✗ | D7: no | E7: no | F7: ✗ | G7: no | H7: no | I7: no | J7: ✗ | K7: ✗ | L7: no | M7: no | N7: Class Level Method Level | O7: ~Monitoring Cycle of 1s mentioned in (Noureddine et al. 2012) | P7: no | Q7: no | R7: Model-based (TDP) | S7: 1) Uses OS provided per-process (PID)resources utilisation to allocate energy to process (JVM) 2a)A version with statistical sampling to allocate energy to methods/classes 2b) A version with automatic bytecode instrumentation to attribute energy to methods/classes | T7: Not modeled | U7: Reported in (Noureddine et al. 2012; (Noureddine et al. 2015)) | W7: Two methods available: 1) Statistical Sampling of Call Stack --> No Code Modification 2) Source Code Instrumentation (i.e. time markers around functions) | X7: Reported in (Noureddine et al. 2012; (Noureddine et al. 2015)) | Z7: ✗ | AA7: ✗ | AB7: no | AC7: no | AD7: ✗ | AF7: no | AG7: no | AH7: No | AI7: No | AJ7: No | AK7: No | AL7: No | AM7: Open-Source
B8: Scaphandre | C8: ✗(RAPL) | D8: ✗(RAPL) | E8: no | F8: no | G8: no | I8: ✗ | J8: ✗ | K8: no | L8: ✗ | M8: no | N8: Node Level (BM/VM) Pod-Level Container-Level Process-level | O8: 1Hz (Max 28Hz If modified as in (Raffin and Trystram 2024)) | P8: no | Q8: ✗(RAPL) | R8: ✗(Used for container allocation or system-level estimations in virtualised context ) | W8: no | Z8: ✗ (Linux System/Windows) | AA8: ✗ | AB8: no | AC8: no | AD8: ✗ | AE8: no | AF8: no | AG8: no | AH8: Support for VM "exposing System-level metrics from host to VM" | AI8: ✗ | AJ8: ✗ | AL8: no : "No, until your cloud provider uses scaphandre on its hypervisors"
B9: IgProf (Energy module) | C9: ✗(RAPL) | D9: ✗(RAPL) | E9: no | F9: no | G9: no | H9: no | I9: no | J9: ✗ | K9: no | L9: no | M9: no | N9: Function Level | O9: ~5ms sampling interval in (Khan et al. 2015) | P9: no | Q9: ✗ (RAPL throush PAPI) | R9: no | S9: 1) Allocate all RAPL system energy to process it is attached to 2) Statistical Sampling (stack trace) to allocate energy to functions | T9: Not modeled | U9: Qualitatively Reported in (Khan et al. 2015) | W9: Mostly statistical sampling --> no code modification | X9: Not reported for Energy module | Y9: Runs as an attached library to the profiled process | Z9: ✗ | AA9: ✗ | AB9: no | AC9: no | AD9: ✗ | AE9: No | AF9: No | AG9: No | AH9: No | AI9: No | AJ9: No | AK9: No | AL9: No | AM9: Open-Source | AN9: Not maintained since 2024 | AO9: Limited to not existing for the energy module (https://igprof.org/index.html) | AP9: Khan, Kashif, Filip Nybäck, Zhonghong Ou, et al. 2015. Energy Profiling Using IgProf. In Proceedings - 2015 IEEE/ACM 15th International Symposium on Cluster, Cloud, and Grid Computing, CCGrid 2015. https://doi.org/10.1109/CCGrid.2015.118.
B10: PowerJoular | C10: ✗(RAPL) | D10: ✗(RAPL) | E10: ✗(NVIDIA SMI) (computers and servers | F10: no | G10: no | H10: no | I10: no | J10: ✗ | K10: no | L10: no | M10: no | N10: Application Level (All its PIDs) Process level (PID) | O10: ~1s | P10: no | Q10: ✗ (RAPL throush powercap) | R10: polynomial regression For Rasberry Pi | S10: 1) Allocation through Processes CPU utilization | T10: Not modeled | U10: btw 0.3% and 3.83% on RaspberryPie (Noureddine [2021] 2022) | W10: No | X10: Not reported but supposed to be low (1s sampling rate + written in Ada (low carbon language(Noureddine [2021] 2022))) | Y10: Command line tool, export to csv | Z10: ✗ | AA10: ✗ | AB10: no | AC10: ✗ | AD10: ✗ | AE10: ✗(specific models) | AF10: ✗(CPU energy on specific models) | AG10: No | AH10: Support for VM "exposing System-level metrics in a shared file from host to VM" | AI10: Support for Container "exposing System-level metrics in a shared file from host to VM" | AJ10: No | AK10: Yes if provided by host | AL10: No | AM10: Open-Source | AN10: Active (Last Commit in 2026) | AO10: Concice documentation : https://joular.github.io/powerjoular/overview.html | AP10: Noureddine, Adel. (2021) 2022. ‘PowerJoular and JoularJX: Multi-Platform Software Power Monitoring Tools’. In Proceedings of the 18th International Conference on Intelligent Environments, Ada. Intelligent Environments. March 22; IEEE, released. https://doi.org/10.1109/IE54923.2022.9826760. | AQ10: PowerJoular is aimed to software developers, system administrators and to automated tools, with a goal to help these users understand the power consumption of their devices and software (Noureddine [2021] 2022)
B11: JoularJX | C11: ✗(RAPL) | D11: ✗(RAPL) | E11: ✗(NVIDIA SMI) (computers and servers | F11: no | G11: no | H11: no | I11: no | J11: ✗ | K11: no | L11: no | M11: no | N11: Function Level | O11: ~10ms | P11: no | Q11: ✗ (RAPL throush powercap) | R11: polynomial regression For Rasberry Pi | S11: 1) Allocation through CPU utilization for Java Threads (1s) 2) Statistical sampling of thread stack trace(10ms) | T11: Not modeled | W11: no: statistical sampling | X11: Not reported | Y11: Command line tool, export to csv | Z11: ✗ | AA11: ✗ | AB11: no | AC11: ✗ | AD11: ✗ | AE11: ✗(specific models) | AF11: No | AG11: No | AH11: ✗ | AI11: No | AJ11: No | AK11: Yes if provided by host | AL11: No | AM11: Open-Source | AN11: Active (Last Commit in 2026) | AO11: Concice documentation : https://joular.github.io/powerjoular/overview.html | AQ11: Designed for software Developers
B12: Joular Core | C12: ✗ | D12: ✗ | E12: ✗ | F12: no | G12: no | H12: no | I12: ✗ | J12: ✗ | K12: no | L12: no | M12: no | N12: Application Level (All its PIDs) Process level (PID) | O12: ~1s | P12: no | Q12: ✗ (RAPL (linux/windows) or powerMetrics (Mac)) | R12: For Rasberry Pi | S12: 1) Allocation through Processes CPU utilization | T12: Baseline modeled and substracted before allocation | U12: Not reported | W12: No | X12: Not reported | Y12: Command line tool or Gui | Z12: ✗ | AA12: ✗ | AB12: no | AC12: ✗ | AD12: ✗ | AE12: ✗ | AF12: no reported | AG12: ✗ | AH12: Support for VM "exposing System-level metrics in a shared file from host to VM" | AI12: Support for Container "exposing System-level metrics in a shared file from host to VM" | AJ12: No | AK12: Yes if provided by host | AL12: No | AM12: Open-Source | AN12: Active (Last Commit 2026) | AO12: Concice documentation : https://joular.github.io/joularcore/ | AQ12: Power Core is aimed to software developers, system administrators and to automated tools, with a goal to help these users understand the power consumption of their devices and software (Noureddine [2021] 2022)
B13: PETRA | C13: ✗ | I13: ✗ | J13: ✗ | N13: Method-Level | O13: ~ms | P13: no | Q13: no | R13: OS signals + power profiles | S13: Time-based allocation (knows exactly entry/exit events of method) | U13: Mean relative error: ~1% overall | W13: Needs to run app in debug mode to access method traces | Z13: no | AA13: no | AB13: ✗ | AC13: no | AD13: no | AE13: no | AF13: no | AG13: no

Sheet Taxonomy
B2: Tool Name | D2: Granularity | L2: Measurement Sources | AK2: Allocation Model | AQ2: Virtualised environment support | AU2: Operational Constraints | BN2: Maturity and ecosystem
D3: Virtual Machine-Level | E3: Pod-Level | F3: Container-Level | G3: Application-Level (Sum of PIDs) | H3: Process-Level | I3: Thread-Level | J3: Code Section-Level (i.e. class, method) | L3: CPU | Q3: DRAM | V3: GPU | AA3: Network (NIC) | AF3: System | AK3: Activity Share Estimation | AO3: BaselineModelling and Calibration | AQ3: Pretrained Model | AR3: Two instances : host exposing VM-level metrics to guest through shared file | AS3: Delegated to another tool | AU3: Accuracy validation | AV3: Temporal resolution | AW3: Runtime overhead | AX3: Code modification | AY3: Privilege | AZ3: Platform Compatibility | BN3: Deployment complexity | BO3: Availability and licensing | BP3: Maintenance status | BQ3: Documentation quality | BR3: Case Studies | BS3: Community adoption | BT3: Extra Metrics
L4: Hardware-Level Energy Estimation | O4: Proxy for Hardware Activity Share of Software | Q4: Hardware-Level Energy Estimation | T4: Software Activity Share Proxy | V4: Hardware-Level Energy Estimation | Y4: Software Activity Share Proxy | AA4: Hardware-Level Energy Estimation | AD4: Software Activity Share Proxy | AF4: Hardware-Level Energy Estimation | AI4: Software Activity Share Proxy | AK4: Directly proportional to Proxy | AL4: Proxy Reconstruction | AM4: Statistical Sampling | AN4: Execution Time Markers | AZ4: Desktop/ Laptop | BA4: Server | BB4: Single Board Computer (e.g. Rasperry Pi) | BC4: x86 | BD4: ARM | BE4: Apple Silicon | BF4: OS | BI4: Virtual machines | BJ4: Containers | BK4: Kubernetes integration | BL4: Specific Language | BT4: Network I/O | BU4: Disk I/O | BV4: CO2e
L5: External Power Meter | M5: Hardware-Exposed Energy Interface | N5: Model -based | Q5: External Power Meter | R5: Hardware-Exposed Energy Interface | S5: Model -based | V5: External Power Meter | W5: Hardware-Exposed Energy Interface | X5: Model -based | AA5: External Power Meter | AB5: Hardware-Exposed Energy Interface | AC5: Model -based | AF5: External Power Meter | AG5: Hardware-Exposed Energy Interface | AH5: Model -based | BF5: Linux | BG5: Windows | BH5: MacOS
B7: Scaphandre | D7: ✗ | E7: ✗ | F7: ✗ | G7: ✗ | H7: ✗ | I7: no | J7: no | L7: no | M7: no | N7: no | O7: no | Q7: no | R7: no | S7: no | T7: no | V7: no | W7: no | X7: no | Y7: no | AA7: no | AB7: no | AC7: no | AD7: no | AF7: no | AG7: ✗(RAPL) | AH7: no | AI7: OS-provided PID CPU % | AK7: ✗ | AL7: no | AM7: no | AN7: no | AO7: no | AQ7: no | AR7: ✗ | AS7: no | AV7: 1Hz (Max 28Hz If modified as in (Raffin and Trystram 2024)) | AX7: no | AZ7: ✗ | BA7: ✗ | BB7: no | BC7: ✗ | BD7: no | BE7: no | BF7: ✗ | BG7: ✗ | BH7: no | BI7: ✗ | BJ7: ✗ | BK7: ✗ | BL7: no | BT7: no | BU7: ✗ | BV7: no
B8: Kepler ≥ 0.10 | D8: ✗ | E8: ✗ | F8: ✗ | G8: ✗ | H8: ✗ | I8: no | J8: no | L8: no | M8: ✗ (RAPL) | N8: ✗Regression-based models for VM deployment | O8: OS-provided PID CPU % Cgroups Stat | Q8: no | R8: ✗(RAPL) | S8: no | T8: OS-provided PID CPU % Cgroups Stat | V8: no | W8: ✗(NVLM) | X8: no | Y8: NVLM-provided (i.e. driver) per-process SM utilization | AA8: no | AB8: no | AC8: no | AD8: no | AF8: ✗(IPMI, ACPI) | AG8: no | AH8: Regression-based model | AI8: OS-provided PID CPU % Cgroups Stat | AK8: ✗ | AL8: no | AM8: no | AN8: no | AO8: Modeled and allocated proportionnaly to processes size | AQ8: Regression model (# cores and OS-provided Resource Utilisation metrics as input) | AR8: no ( (CNCF 2023) mentions a planned "passthrough" mode for VM deployment which expose VM energy in a shared file. | AS8: no | AU8: Reported MSE of 0.01 in (Amaral et al. 2023) | AV8: ~ms at RAPL read level Effective resolution = Prometheus scrape interval (typically 1s–30s depending on configuration) | AX8: no | AZ8: ✗ | BA8: ✗ | BB8: no | BC8: ✗ | BD8: no | BE8: no | BF8: ✗ | BG8: no | BH8: no | BI8: ✗ | BJ8: ✗ | BK8: ✗ | BL8: no | BN8: Runs as DaemonSet on each node Linux-based nodes required | BO8: Open-Source (CNCF Sandbox project) | BP8: Active (Last Commit in March 2026) | BQ8: Extensive Documentation (https://sustainable-computing.io/) | BR8: Centofanti, Carlo, José Santos, Venkateswarlu Gudepu, and Koteswararao Kondepu. 2024. ‘Impact of Power Consumption in Containerized Clouds: A Comprehensive Analysis of Open-Source Power Measurement Tools’. Computer Networks 245 (May): 110371. https://doi.org/10.1016/j.comnet.2024.110371. | BS8: Designed for edge/cloud/ K8s Operators | BT8: no | BU8: no | BV8: no
B9: Kepler ≤ v0.9 | D9: ✗ | E9: ✗ | F9: ✗ | G9: ✗ | H9: ✗ | I9: no | J9: no | L9: no | M9: ✗ (RAPL) | N9: ✗Regression-based models for VM deployment | O9: PID runtime + HPC vector (cycles, instructions, cache misses) through eBPF tracing | Q9: no | R9: ✗(RAPL) | S9: no | T9: PID runtime + HPC vector (cycles, instructions, cache misses) through eBPF tracing | V9: no | W9: ✗(NVLM) | X9: no | Y9: NVLM-provided (i.e. driver) per-process SM utilization | AA9: no | AB9: no | AC9: no | AD9: no | AF9: ✗(IPMI, ACPI) | AG9: no | AH9: Regression-based trained power model | AI9: PID runtime + HPC vector (cycles, instructions, cache misses) through eBPF tracing | AK9: no | AL9: ✗ (from HPC vector (cycles, instructions, cache misses)) | AM9: no | AN9: no | AO9: Modeled and allocated proportionnaly to processes size | AQ9: Regression model (# cores and OS-provided Resource Utilisation metrics as input) | AR9: no ( (CNCF 2023) mentions a planned "passthrough" mode for VM deployment which expose VM energy in a shared file. | AS9: no | AU9: Reported MSE of 0.01 in (Amaral et al. 2023) | AV9: eBPF data collected every 3s. | AX9: no | AZ9: ✗ | BA9: ✗ | BB9: no | BC9: ✗ | BD9: no | BE9: no | BF9: ✗ | BG9: no | BH9: no | BI9: ✗ | BJ9: ✗ | BK9: ✗ | BL9: no | BN9: Runs as DaemonSet on each node Linux-based nodes required | BO9: Open-Source (CNCF Sandbox project) | BP9: Active (Last Commit in March 2026) | BQ9: Extensive Documentation (https://sustainable-computing.io/) | BR9: Centofanti, Carlo, José Santos, Venkateswarlu Gudepu, and Koteswararao Kondepu. 2024. ‘Impact of Power Consumption in Containerized Clouds: A Comprehensive Analysis of Open-Source Power Measurement Tools’. Computer Networks 245 (May): 110371. https://doi.org/10.1016/j.comnet.2024.110371. | BS9: Designed for edge/cloud/ K8s Operators | BT9: no | BU9: no | BV9: no
B10: Green Metric Tool | D10: no | E10: no | F10: ✗ | G10: no | H10: no | I10: no | J10: ✗(SCI functionnality) | L10: ✗(Compatible with certain Metric Providers) | M10: ✗(RAPL) | N10: ✗1) XGBoost model (TDP, Machine Specs and CPU%) 2) Analytical Model(TDP, #CPUchips and CPU %) | O10: OS-provided PID CPU % Cgroups Stat Code Special Print (Code Section) | Q10: no | R10: ✗(RAPL) | S10: no | T10: OS-provided PID CPU % Cgroups Stat (Container) Code Special Print (Code Section) | V10: no | W10: ✗(NVLM) | X10: no | Y10: OS-provided PID CPU % Cgroups Stat Code Special Print (Code Section) | AA10: no | AB10: no | AC10: no | AD10: no | AF10: ✗ | AG10: ✗(RAPL PSYS Domain) | AH10: ✗1) XGBoost model (TDP, Machine Specs and CPU%) 2) Analytical Model(TDP, #CPUchips and CPU %) | AI10: OS-provided PID CPU % Cgroups Stat (container) Code Special Print (Code Section) | AK10: ✗ | AL10: no | AM10: no | AN10: ✗(SCI functionnality) | AO10: Modeled and allocated to container according to OS-provided PID CPU % | AQ10: 1) XGBoost model (# cores TDP, Machine Specs and CPU%) 2) Analytical Model(TDP, #CPUchips and CPU %) | AR10: no | AS10: no | AU10: Relative to metric providers : For RAPL which is extensively used by the GMT : https://www.green-coding.io/case-studies/rapl-and-sgx/ | AV10: ~ms Configurable for each metric provider (1ms for RAPL metric provider) | AW10: Designed to be low (uses containers). GMT allows to estimate it through a special script : calibrate.py | AX10: ✗(Manual : For SCI) | AY10: Run as Root Installs RAPL Kernel Module | AZ10: ✗ | BA10: ✗ | BB10: no | BC10: ✗ | BD10: Few Metric Providers with limited Accuracy | BE10: Depends on Metric Provider in Use | BF10: ✗ | BG10: no | BH10: no | BI10: ✗ | BJ10: ✗ | BK10: no | BL10: no | BN10: Python App + Redis DB + Web-based API & Front-end for data analysis Hosted Service (paid) | BO10: Open-Source | BP10: Active (Last Commit in Feb 2026) | BQ10: Extensive Documentation (https://docs.green-coding.io/) | BR10: Hoffmann, Geerd-Dietger, and Verena Majuntke. 2025. ‘Green Metrics Tool: Measuring for Fun and Profit’. arXiv:2506.23967. Preprint, arXiv, June 30. https://doi.org/10.48550/arXiv.2506.23967. Kayembe, Jason, Iness Ben Guirat, and Jan Tobias Mühlberg. 2025. ‘Exploring Privacy and Security as Drivers for Environmental Sustainability in Cloud-Based Office Solutions’. arXiv:2506.23866. Preprint, arXiv, July 4. https://doi.org/10.48550/arXiv.2506.23866. | BS10: Designed for developers to integrate SCI in dev Used in a few academic researches | BT10: ✗ | BU10: ✗ | BV10: ✗
B11: BitWatts (PowerAPI extension) | D11: ✗ | E11: no | F11: no | G11: ✗ | H11: ✗ | I11: no | J11: no | L11: no | M11: no | N11: ✗Polynomial regression based on per-PID-and-per-core-HPCs (unhalted cycles + reference cycles) and CPU frequency | O11: no | Q11: no | R11: no | S11: no | T11: no | V11: no | W11: no | X11: no | Y11: no | AA11: no | AB11: no | AC11: no | AD11: no | AF11: no | AG11: no | AH11: no | AI11: no | AK11: no | AL11: no | AM11: no | AN11: no | AO11: no | AQ11: no | AR11: ✗ | AS11: no | AU11: Reported 2% median error (Colmant et al. 2015) | AV11: 10hz | AW11: Reported average of 5.4W (Colmant et al. 2015) | AX11: no | AZ11: ✗ | BA11: ✗ | BB11: no | BC11: ✗ | BD11: no | BE11: no | BF11: ✗ | BG11: no | BH11: no | BI11: ✗ | BJ11: no | BK11: no | BL11: no | BT11: no | BU11: no | BV11: no
B13: e-Surgeon (PowerAPI) | D13: no | E13: no | F13: no | G13: no | H13: ✗ | I13: no | J13: no | L13: no | M13: no | N13: ✗ Linear Regression Model (HPC : "instructions", "cache references", "cache misses" | O13: OS-provided PID CPU % | Q13: no | R13: no | S13: no | T13: no | V13: no | W13: no | X13: no | Y13: no | AA13: no | AB13: no | AC13: ✗ | AD13: OS provided per-process (PID)Network I/O | AF13: no | AG13: no | AH13: ✗(TDP) | AI13: OS-provided PID CPU % | AK13: ✗ | AL13: no | AM13: no | AN13: no | AO13: no | AQ13: no | AR13: no | AS13: no | AU13: Reported in (Noureddine et al. 2012; (Noureddine et al. 2015)) | AV13: ~Monitoring Cycle of 1s mentioned in (Noureddine et al. 2012) | AW13: 1.79% Reported in (Noureddine et al. 2012; (Noureddine et al. 2015)) | AX13: no | AZ13: ✗ | BA13: ✗ | BB13: no | BC13: ✗ | BE13: no | BF13: ✗ | BG13: no | BH13: no | BI13: no | BJ13: no | BK13: no | BL13: no | BO13: Open-Source | BT13: ✗ | BU13: no | BV13: no
B14: BitWatts | D14: no | E14: no | F14: no | G14: no | H14: ✗ | I14: no | J14: no | L14: no | M14: no | N14: ✗HPC vector (cycles, instructions, cache misses) | O14: OS-provided PID CPU % | Q14: no | R14: no | S14: no | T14: no | V14: no | W14: no | X14: no | Y14: no | AA14: no | AB14: no | AC14: no | AD14: no | AF14: no | AG14: no | AH14: ✗ HPC (cycles, instructions, cache misses) vector | AI14: OS-provided PID CPU % | AK14: ✗ | AL14: no | AM14: no | AN14: no | AO14: no | AQ14: no | AR14: no | AS14: no | AV14: ~Monitoring Cycle of 1s mentioned in (Noureddine et al. 2012) | AW14: Reported in (Noureddine et al. 2012; (Noureddine et al. 2015)) | AX14: no | AZ14: ✗ | BA14: ✗ | BB14: no | BC14: ✗ | BE14: no | BF14: ✗ | BG14: no | BH14: no | BI14: no | BJ14: no | BK14: no | BL14: no | BO14: Open-Source | BT14: ✗ | BU14: no | BV14: no
B15: PowerJoular | D15: ✗ | E15: no | F15: no | G15: ✗ | H15: ✗ | I15: no | J15: no | L15: no | M15: ✗ (RAPL throush powercap) | N15: no | O15: OS-provided PID CPU % | Q15: no | R15: ✗(RAPL) | S15: no | T15: PID CPU % | V15: no | W15: ✗(NVIDIA-SMI, AMD-SMI) (computers and servers) | X15: no | Y15: PID GPU % (from driver API) | AA15: no | AB15: no | AC15: no | AD15: no | AF15: no | AG15: no | AH15: polynomial regression For Rasberry Pi | AI15: OS-provided PID CPU % | AK15: ✗ | AL15: no | AM15: no | AN15: no | AO15: no | AQ15: no | AR15: ✗ | AS15: no | AU15: btw 0.3% and 3.83% on RaspberryPie (Noureddine [2021] 2022) | AV15: ~1s | AW15: no : Not reported but supposed to be low (1s sampling rate + written in Ada (low carbon language(Noureddine [2021] 2022))) | AX15: no | AY15: Run as Root Use Powercap for RAPL access | AZ15: ✗ | BA15: ✗ | BB15: ✗ | BC15: ✗ | BD15: ✗(specific models) | BE15: no | BF15: ✗ | BG15: no | BH15: no | BI15: ✗ | BJ15: ✗ | BK15: no | BL15: no | BN15: Command line tool, export to csv | BO15: Open-Source | BP15: Active (Last Commit in 2026) | BQ15: Concice documentation : https://joular.github.io/powerjoular/overview.html | BR15: Noureddine, Adel. (2021) 2022. ‘PowerJoular and JoularJX: Multi-Platform Software Power Monitoring Tools’. In Proceedings of the 18th International Conference on Intelligent Environments, Ada. Intelligent Environments. March 22; IEEE, released. https://doi.org/10.1109/IE54923.2022.9826760. | BS15: Power Core is aimed to software developers, system administrators and to automated tools, with a goal to help these users understand the power consumption of their devices and software (Noureddine [2021] 2022) | BT15: no | BU15: no | BV15: no
B16: Joular Core | D16: ✗ | E16: no | F16: no | G16: ✗ | H16: ✗ | I16: no | J16: no | L16: no | M16: ✗ (RAPL (linux/windows) or powerMetrics (Mac)) | N16: no | O16: OS-provided PID CPU % | Q16: no | R16: ✗(RAPL) | S16: no | T16: PID CPU % | V16: no | W16: ✗(NVIDIA-SMI, AMD-SMI) (computers and servers) | X16: no | Y16: PID GPU % (from driver API) | AA16: no | AB16: no | AC16: no | AD16: no | AF16: no | AG16: ✗(RAPL) | AH16: polynomial regression For Rasberry Pi | AI16: OS-provided PID CPU % | AK16: ✗ | AL16: no | AM16: no | AN16: no | AO16: Modeled and substracted before allocation | AQ16: no | AR16: ✗ | AS16: no | AU16: no | AV16: ~1s | AW16: no | AX16: no | AZ16: ✗ | BA16: ✗ | BB16: ✗ | BC16: ✗ | BD16: ✗ | BE16: ✗ | BF16: ✗ | BG16: ✗ | BH16: ✗ | BI16: ✗ | BJ16: ✗ | BK16: no | BL16: no | BN16: Command line tool or Gui | BO16: Open-Source | BP16: Active (Last Commit 2026) | BQ16: Concice documentation : https://joular.github.io/joularcore/ | BS16: Power Core is aimed to software developers, system administrators and to automated tools, with a goal to help these users understand the power consumption of their devices and software (Noureddine [2021] 2022) | BT16: no | BU16: no | BV16: no
B18: e-Surgeon (eJalen) | D18: no | E18: no | F18: no | G18: no | H18: no | I18: ✗ | J18: ✗ | L18: no | M18: no | N18: ✗ (TDP) Through PowerAPI | O18: 1) Time Markers : JVM byte code instrumentation / 2) Call stack | Q18: no | R18: no | S18: no | T18: no | V18: no | W18: no | X18: no | Y18: no | AA18: no | AB18: no | AC18: ✗(Through PowerAPI) | AD18: getInputStream() getOutputStream() calls | AF18: no | AG18: no | AH18: no | AI18: no | AK18: ✗ (For NIC) | AL18: no | AM18: ✗(for CPU : call-stack sampling version) | AN18: ✗ (for CPU : bytecode instrumentation version) | AO18: no | AQ18: no | AR18: no | AS18: no | AU18: Reported in (Noureddine et al. 2012; (Noureddine et al. 2015)) | AV18: ~Monitoring Cycle of 1s mentioned in (Noureddine et al. 2012) | AW18: 380% : Reported in (Noureddine et al. 2012; (Noureddine et al. 2015)) | AX18: ✗ (Automatic : Byte Code Instrumentation version ) | AZ18: ✗ | BA18: ✗ | BB18: no | BC18: ✗ | BE18: no | BI18: no | BJ18: no | BK18: no | BL18: Java | BO18: Open-Source | BT18: ✗ | BU18: no | BV18: no
B19: JoularJX | D19: no | E19: no | F19: no | G19: no | H19: no | I19: ✗ | J19: ✗ | L19: no | M19: ✗ (RAPL through powercap) | N19: no | O19: 1) OS-provided PID CPU % for Java Threads through JVM instrumentation 2) Call Stack | Q19: no | R19: ✗(RAPL) Through Power Joular | S19: no | T19: 1) OS-provided PID CPU % for Java Threads through JVM instrumentation 2) Statistical sampling of thread stack trace | V19: no | W19: ✗(NVIDIA SMI) (computers and servers through Power Joular | X19: no | Y19: 1) OS-provided PID CPU % for Java Threads through JVM instrumentation 2) Statistical sampling of thread stack trace | AA19: no | AB19: no | AC19: no | AD19: no | AF19: no | AG19: no | AH19: polynomial regression For Rasberry Pi | AI19: 1) OS-provided PID CPU % for Java Threads through JVM instrumentation 2) Statistical sampling of thread stack trace | AK19: ✗(for threads) | AL19: no | AM19: ✗ | AN19: no | AO19: no | AQ19: no | AR19: no | AS19: Uses PowerJoular | AV19: ~10ms (code section) ~1s (thread) | AX19: no | AZ19: ✗ | BA19: ✗ | BB19: ✗ | BC19: ✗ | BD19: ✗(specific models) | BE19: no | BF19: ✗ | BG19: ✗ | BH19: ✗ | BI19: ✗ | BJ19: ✗ | BK19: no | BL19: Java | BN19: Command line tool, export to csv | BO19: Open-Source | BP19: Active (Last Commit in 2026) | BQ19: Concice documentation : https://joular.github.io/powerjoular/overview.html | BS19: Designed for software Developements | BT19: no | BU19: no | BV19: no
B20: IgProf (Energy module) | D20: ✗ | E20: no | F20: no | G20: ✗ | H20: ✗ | I20: ✗ | J20: ✗ | L20: no | M20: ✗ (RAPL throush PAPI) | N20: no | O20: Call stack | Q20: no | R20: ✗(RAPL) | S20: no | T20: Call stack sampling | V20: no | W20: no | X20: no | Y20: no | AA20: no | AB20: no | AC20: no | AD20: no | AF20: no | AG20: ✗ (RAPL throush PAPI) | AH20: no | AI20: Call stack sampling | AK20: no | AL20: no | AM20: ✗(1) Allocate all RAPL system energy to process it is attached to 2) Statistical Sampling (stack trace) to allocate energy to functions) | AN20: no | AO20: no | AQ20: no | AR20: no | AS20: no | AU20: Qualitatively Reported in (Khan et al. 2015) | AV20: ~5ms sampling interval in (Khan et al. 2015) | AX20: no | AY20: User Mode: Queries RAPL through PAPI | AZ20: ✗ | BA20: ✗ | BB20: no | BC20: ✗ | BD20: no | BE20: no | BI20: no | BJ20: no | BK20: no | BL20: no | BN20: Runs as an attached library to the profiled process | BO20: Open-Source | BP20: Not maintained since 2024 | BQ20: Limited to not existing for the energy module (https://igprof.org/index.html) | BR20: Khan, Kashif, Filip Nybäck, Zhonghong Ou, et al. 2015. Energy Profiling Using IgProf. In Proceedings - 2015 IEEE/ACM 15th International Symposium on Cluster, Cloud, and Grid Computing, CCGrid 2015. https://doi.org/10.1109/CCGrid.2015.118. | BT20: no | BU20: no | BV20: no
B21: jRAPL | D21: no | E21: no | F21: no | G21: no | H21: no | I21: no | J21: ✗ | L21: no | M21: ✗ (RAPL through linux MSR kernel module) | N21: no | O21: Time Markers | Q21: no | R21: ✗ (RAPL through linux MSR kernel module) | S21: no | T21: Time Markers | V21: no | W21: no | X21: no | Y21: no | AA21: no | AB21: no | AC21: no | AD21: no | AF21: no | AG21: ✗ (RAPL through linux MSR kernel module) | AH21: no | AI21: Time Markers | AK21: no | AL21: no | AM21: no | AN21: ✗ | AO21: no | AQ21: no | AR21: no | AS21: no | AU21: no | AV21: ~1ms | AW21: no | AX21: ✗(Manual) | AY21: "Run as Root Installs RAPL Kernel Module" | AZ21: ✗ | BA21: ✗ | BB21: no | BC21: ✗ | BD21: no | BE21: no | BF21: ✗ | BG21: no | BH21: no | BI21: no | BJ21: no | BK21: no | BL21: Java | BN21: Java Library to load from any Java source code. Developer just needs to put API calls (statCheck) before and after a code block. The energy consumption is the difference between the two readings | BO21: Open-Source | BP21: Not maintained since 2018 | BQ21: Limited | BR21: Liu, Kenan, Gustavo Pinto, and Yu David Liu. 2015. ‘Data-Oriented Characterization of Application-Level Energy Optimization’. In Fundamental Approaches to Software Engineering, edited by Alexander Egyed and Ina Schaefer. Springer. https://doi.org/10.1007/978-3-662-46675-9_21. | BS21: Designed for software Developements | BT21: no | BU21: no | BV21: no

Sheet Design Space
C6: Tool Name | E6: Granularity | M6: Measurement Sources | AL6: Allocation Model | AR6: Virtualised environment support
E7: Virtual Machine-Level | F7: Pod-Level | G7: Container-Level | H7: Application-Level (Sum of PIDs) | I7: Process-Level | J7: Thread-Level | K7: Code Section-Level | M7: CPU | R7: DRAM | W7: GPU | AB7: Network (NIC) | AG7: System | AL7: Activity Share Estimation | AP7: Baseline Modelling and Calibration | AR7: Pretrained Model | AS7: Two instances : host exposing VM-level metrics to guest through shared file | AT7: Delegated to another tool
